2025-08-31 21:17:12,695 : ERROR : BINANCE_FUTURES: Failed to parse symbol information: ('Connection aborted.', ConnectionResetError(54, 'Connection reset by peer'))
Traceback (most recent call last):
  File "/Users/aming/anaconda3/envs/quant/lib/python3.8/site-packages/urllib3/connectionpool.py", line 789, in urlopen
    response = self._make_request(
  File "/Users/aming/anaconda3/envs/quant/lib/python3.8/site-packages/urllib3/connectionpool.py", line 490, in _make_request
    raise new_e
  File "/Users/aming/anaconda3/envs/quant/lib/python3.8/site-packages/urllib3/connectionpool.py", line 466, in _make_request
    self._validate_conn(conn)
  File "/Users/aming/anaconda3/envs/quant/lib/python3.8/site-packages/urllib3/connectionpool.py", line 1095, in _validate_conn
    conn.connect()
  File "/Users/aming/anaconda3/envs/quant/lib/python3.8/site-packages/urllib3/connection.py", line 730, in connect
    sock_and_verified = _ssl_wrap_socket_and_match_hostname(
  File "/Users/aming/anaconda3/envs/quant/lib/python3.8/site-packages/urllib3/connection.py", line 909, in _ssl_wrap_socket_and_match_hostname
    ssl_sock = ssl_wrap_socket(
  File "/Users/aming/anaconda3/envs/quant/lib/python3.8/site-packages/urllib3/util/ssl_.py", line 469, in ssl_wrap_socket
    ssl_sock = _ssl_wrap_socket_impl(sock, context, tls_in_tls, server_hostname)
  File "/Users/aming/anaconda3/envs/quant/lib/python3.8/site-packages/urllib3/util/ssl_.py", line 513, in _ssl_wrap_socket_impl
    return ssl_context.wrap_socket(sock, server_hostname=server_hostname)
  File "/Users/aming/anaconda3/envs/quant/lib/python3.8/ssl.py", line 500, in wrap_socket
    return self.sslsocket_class._create(
  File "/Users/aming/anaconda3/envs/quant/lib/python3.8/ssl.py", line 1040, in _create
    self.do_handshake()
  File "/Users/aming/anaconda3/envs/quant/lib/python3.8/ssl.py", line 1309, in do_handshake
    self._sslobj.do_handshake()
ConnectionResetError: [Errno 54] Connection reset by peer

During handling of the above exception, another exception occurred:

Traceback (most recent call last):
  File "/Users/aming/anaconda3/envs/quant/lib/python3.8/site-packages/requests/adapters.py", line 667, in send
    resp = conn.urlopen(
  File "/Users/aming/anaconda3/envs/quant/lib/python3.8/site-packages/urllib3/connectionpool.py", line 843, in urlopen
    retries = retries.increment(
  File "/Users/aming/anaconda3/envs/quant/lib/python3.8/site-packages/urllib3/util/retry.py", line 474, in increment
    raise reraise(type(error), error, _stacktrace)
  File "/Users/aming/anaconda3/envs/quant/lib/python3.8/site-packages/urllib3/util/util.py", line 38, in reraise
    raise value.with_traceback(tb)
  File "/Users/aming/anaconda3/envs/quant/lib/python3.8/site-packages/urllib3/connectionpool.py", line 789, in urlopen
    response = self._make_request(
  File "/Users/aming/anaconda3/envs/quant/lib/python3.8/site-packages/urllib3/connectionpool.py", line 490, in _make_request
    raise new_e
  File "/Users/aming/anaconda3/envs/quant/lib/python3.8/site-packages/urllib3/connectionpool.py", line 466, in _make_request
    self._validate_conn(conn)
  File "/Users/aming/anaconda3/envs/quant/lib/python3.8/site-packages/urllib3/connectionpool.py", line 1095, in _validate_conn
    conn.connect()
  File "/Users/aming/anaconda3/envs/quant/lib/python3.8/site-packages/urllib3/connection.py", line 730, in connect
    sock_and_verified = _ssl_wrap_socket_and_match_hostname(
  File "/Users/aming/anaconda3/envs/quant/lib/python3.8/site-packages/urllib3/connection.py", line 909, in _ssl_wrap_socket_and_match_hostname
    ssl_sock = ssl_wrap_socket(
  File "/Users/aming/anaconda3/envs/quant/lib/python3.8/site-packages/urllib3/util/ssl_.py", line 469, in ssl_wrap_socket
    ssl_sock = _ssl_wrap_socket_impl(sock, context, tls_in_tls, server_hostname)
  File "/Users/aming/anaconda3/envs/quant/lib/python3.8/site-packages/urllib3/util/ssl_.py", line 513, in _ssl_wrap_socket_impl
    return ssl_context.wrap_socket(sock, server_hostname=server_hostname)
  File "/Users/aming/anaconda3/envs/quant/lib/python3.8/ssl.py", line 500, in wrap_socket
    return self.sslsocket_class._create(
  File "/Users/aming/anaconda3/envs/quant/lib/python3.8/ssl.py", line 1040, in _create
    self.do_handshake()
  File "/Users/aming/anaconda3/envs/quant/lib/python3.8/ssl.py", line 1309, in do_handshake
    self._sslobj.do_handshake()
urllib3.exceptions.ProtocolError: ('Connection aborted.', ConnectionResetError(54, 'Connection reset by peer'))

During handling of the above exception, another exception occurred:

Traceback (most recent call last):
  File "/Users/aming/anaconda3/envs/quant/lib/python3.8/site-packages/cryptofeed/exchange.py", line 103, in symbol_mapping
    data.append(cls.http_sync.read(addr, json=True, uuid=cls.id))
  File "/Users/aming/anaconda3/envs/quant/lib/python3.8/site-packages/cryptofeed/connection.py", line 55, in read
    r = requests.get(address, headers=headers, params=params)
  File "/Users/aming/anaconda3/envs/quant/lib/python3.8/site-packages/requests/api.py", line 73, in get
    return request("get", url, params=params, **kwargs)
  File "/Users/aming/anaconda3/envs/quant/lib/python3.8/site-packages/requests/api.py", line 59, in request
    return session.request(method=method, url=url, **kwargs)
  File "/Users/aming/anaconda3/envs/quant/lib/python3.8/site-packages/requests/sessions.py", line 589, in request
    resp = self.send(prep, **send_kwargs)
  File "/Users/aming/anaconda3/envs/quant/lib/python3.8/site-packages/requests/sessions.py", line 703, in send
    r = adapter.send(request, **kwargs)
  File "/Users/aming/anaconda3/envs/quant/lib/python3.8/site-packages/requests/adapters.py", line 682, in send
    raise ConnectionError(err, request=request)
requests.exceptions.ConnectionError: ('Connection aborted.', ConnectionResetError(54, 'Connection reset by peer'))
2025-08-31 21:23:33,864 : ERROR : COINBASE: Failed to parse symbol information: ('Connection aborted.', ConnectionResetError(54, 'Connection reset by peer'))
Traceback (most recent call last):
  File "/Users/aming/anaconda3/envs/quant/lib/python3.8/site-packages/urllib3/connectionpool.py", line 789, in urlopen
    response = self._make_request(
  File "/Users/aming/anaconda3/envs/quant/lib/python3.8/site-packages/urllib3/connectionpool.py", line 490, in _make_request
    raise new_e
  File "/Users/aming/anaconda3/envs/quant/lib/python3.8/site-packages/urllib3/connectionpool.py", line 466, in _make_request
    self._validate_conn(conn)
  File "/Users/aming/anaconda3/envs/quant/lib/python3.8/site-packages/urllib3/connectionpool.py", line 1095, in _validate_conn
    conn.connect()
  File "/Users/aming/anaconda3/envs/quant/lib/python3.8/site-packages/urllib3/connection.py", line 730, in connect
    sock_and_verified = _ssl_wrap_socket_and_match_hostname(
  File "/Users/aming/anaconda3/envs/quant/lib/python3.8/site-packages/urllib3/connection.py", line 909, in _ssl_wrap_socket_and_match_hostname
    ssl_sock = ssl_wrap_socket(
  File "/Users/aming/anaconda3/envs/quant/lib/python3.8/site-packages/urllib3/util/ssl_.py", line 469, in ssl_wrap_socket
    ssl_sock = _ssl_wrap_socket_impl(sock, context, tls_in_tls, server_hostname)
  File "/Users/aming/anaconda3/envs/quant/lib/python3.8/site-packages/urllib3/util/ssl_.py", line 513, in _ssl_wrap_socket_impl
    return ssl_context.wrap_socket(sock, server_hostname=server_hostname)
  File "/Users/aming/anaconda3/envs/quant/lib/python3.8/ssl.py", line 500, in wrap_socket
    return self.sslsocket_class._create(
  File "/Users/aming/anaconda3/envs/quant/lib/python3.8/ssl.py", line 1040, in _create
    self.do_handshake()
  File "/Users/aming/anaconda3/envs/quant/lib/python3.8/ssl.py", line 1309, in do_handshake
    self._sslobj.do_handshake()
ConnectionResetError: [Errno 54] Connection reset by peer

During handling of the above exception, another exception occurred:

Traceback (most recent call last):
  File "/Users/aming/anaconda3/envs/quant/lib/python3.8/site-packages/requests/adapters.py", line 667, in send
    resp = conn.urlopen(
  File "/Users/aming/anaconda3/envs/quant/lib/python3.8/site-packages/urllib3/connectionpool.py", line 843, in urlopen
    retries = retries.increment(
  File "/Users/aming/anaconda3/envs/quant/lib/python3.8/site-packages/urllib3/util/retry.py", line 474, in increment
    raise reraise(type(error), error, _stacktrace)
  File "/Users/aming/anaconda3/envs/quant/lib/python3.8/site-packages/urllib3/util/util.py", line 38, in reraise
    raise value.with_traceback(tb)
  File "/Users/aming/anaconda3/envs/quant/lib/python3.8/site-packages/urllib3/connectionpool.py", line 789, in urlopen
    response = self._make_request(
  File "/Users/aming/anaconda3/envs/quant/lib/python3.8/site-packages/urllib3/connectionpool.py", line 490, in _make_request
    raise new_e
  File "/Users/aming/anaconda3/envs/quant/lib/python3.8/site-packages/urllib3/connectionpool.py", line 466, in _make_request
    self._validate_conn(conn)
  File "/Users/aming/anaconda3/envs/quant/lib/python3.8/site-packages/urllib3/connectionpool.py", line 1095, in _validate_conn
    conn.connect()
  File "/Users/aming/anaconda3/envs/quant/lib/python3.8/site-packages/urllib3/connection.py", line 730, in connect
    sock_and_verified = _ssl_wrap_socket_and_match_hostname(
  File "/Users/aming/anaconda3/envs/quant/lib/python3.8/site-packages/urllib3/connection.py", line 909, in _ssl_wrap_socket_and_match_hostname
    ssl_sock = ssl_wrap_socket(
  File "/Users/aming/anaconda3/envs/quant/lib/python3.8/site-packages/urllib3/util/ssl_.py", line 469, in ssl_wrap_socket
    ssl_sock = _ssl_wrap_socket_impl(sock, context, tls_in_tls, server_hostname)
  File "/Users/aming/anaconda3/envs/quant/lib/python3.8/site-packages/urllib3/util/ssl_.py", line 513, in _ssl_wrap_socket_impl
    return ssl_context.wrap_socket(sock, server_hostname=server_hostname)
  File "/Users/aming/anaconda3/envs/quant/lib/python3.8/ssl.py", line 500, in wrap_socket
    return self.sslsocket_class._create(
  File "/Users/aming/anaconda3/envs/quant/lib/python3.8/ssl.py", line 1040, in _create
    self.do_handshake()
  File "/Users/aming/anaconda3/envs/quant/lib/python3.8/ssl.py", line 1309, in do_handshake
    self._sslobj.do_handshake()
urllib3.exceptions.ProtocolError: ('Connection aborted.', ConnectionResetError(54, 'Connection reset by peer'))

During handling of the above exception, another exception occurred:

Traceback (most recent call last):
  File "/Users/aming/anaconda3/envs/quant/lib/python3.8/site-packages/cryptofeed/exchange.py", line 103, in symbol_mapping
    data.append(cls.http_sync.read(addr, json=True, uuid=cls.id))
  File "/Users/aming/anaconda3/envs/quant/lib/python3.8/site-packages/cryptofeed/connection.py", line 55, in read
    r = requests.get(address, headers=headers, params=params)
  File "/Users/aming/anaconda3/envs/quant/lib/python3.8/site-packages/requests/api.py", line 73, in get
    return request("get", url, params=params, **kwargs)
  File "/Users/aming/anaconda3/envs/quant/lib/python3.8/site-packages/requests/api.py", line 59, in request
    return session.request(method=method, url=url, **kwargs)
  File "/Users/aming/anaconda3/envs/quant/lib/python3.8/site-packages/requests/sessions.py", line 589, in request
    resp = self.send(prep, **send_kwargs)
  File "/Users/aming/anaconda3/envs/quant/lib/python3.8/site-packages/requests/sessions.py", line 703, in send
    r = adapter.send(request, **kwargs)
  File "/Users/aming/anaconda3/envs/quant/lib/python3.8/site-packages/requests/adapters.py", line 682, in send
    raise ConnectionError(err, request=request)
requests.exceptions.ConnectionError: ('Connection aborted.', ConnectionResetError(54, 'Connection reset by peer'))
2025-09-01 08:36:54,069 : ERROR : COINBASE: Failed to parse symbol information: ('Connection aborted.', ConnectionResetError(54, 'Connection reset by peer'))
Traceback (most recent call last):
  File "/Users/aming/anaconda3/envs/quant/lib/python3.8/site-packages/urllib3/connectionpool.py", line 789, in urlopen
    response = self._make_request(
  File "/Users/aming/anaconda3/envs/quant/lib/python3.8/site-packages/urllib3/connectionpool.py", line 490, in _make_request
    raise new_e
  File "/Users/aming/anaconda3/envs/quant/lib/python3.8/site-packages/urllib3/connectionpool.py", line 466, in _make_request
    self._validate_conn(conn)
  File "/Users/aming/anaconda3/envs/quant/lib/python3.8/site-packages/urllib3/connectionpool.py", line 1095, in _validate_conn
    conn.connect()
  File "/Users/aming/anaconda3/envs/quant/lib/python3.8/site-packages/urllib3/connection.py", line 730, in connect
    sock_and_verified = _ssl_wrap_socket_and_match_hostname(
  File "/Users/aming/anaconda3/envs/quant/lib/python3.8/site-packages/urllib3/connection.py", line 909, in _ssl_wrap_socket_and_match_hostname
    ssl_sock = ssl_wrap_socket(
  File "/Users/aming/anaconda3/envs/quant/lib/python3.8/site-packages/urllib3/util/ssl_.py", line 469, in ssl_wrap_socket
    ssl_sock = _ssl_wrap_socket_impl(sock, context, tls_in_tls, server_hostname)
  File "/Users/aming/anaconda3/envs/quant/lib/python3.8/site-packages/urllib3/util/ssl_.py", line 513, in _ssl_wrap_socket_impl
    return ssl_context.wrap_socket(sock, server_hostname=server_hostname)
  File "/Users/aming/anaconda3/envs/quant/lib/python3.8/ssl.py", line 500, in wrap_socket
    return self.sslsocket_class._create(
  File "/Users/aming/anaconda3/envs/quant/lib/python3.8/ssl.py", line 1040, in _create
    self.do_handshake()
  File "/Users/aming/anaconda3/envs/quant/lib/python3.8/ssl.py", line 1309, in do_handshake
    self._sslobj.do_handshake()
ConnectionResetError: [Errno 54] Connection reset by peer

During handling of the above exception, another exception occurred:

Traceback (most recent call last):
  File "/Users/aming/anaconda3/envs/quant/lib/python3.8/site-packages/requests/adapters.py", line 667, in send
    resp = conn.urlopen(
  File "/Users/aming/anaconda3/envs/quant/lib/python3.8/site-packages/urllib3/connectionpool.py", line 843, in urlopen
    retries = retries.increment(
  File "/Users/aming/anaconda3/envs/quant/lib/python3.8/site-packages/urllib3/util/retry.py", line 474, in increment
    raise reraise(type(error), error, _stacktrace)
  File "/Users/aming/anaconda3/envs/quant/lib/python3.8/site-packages/urllib3/util/util.py", line 38, in reraise
    raise value.with_traceback(tb)
  File "/Users/aming/anaconda3/envs/quant/lib/python3.8/site-packages/urllib3/connectionpool.py", line 789, in urlopen
    response = self._make_request(
  File "/Users/aming/anaconda3/envs/quant/lib/python3.8/site-packages/urllib3/connectionpool.py", line 490, in _make_request
    raise new_e
  File "/Users/aming/anaconda3/envs/quant/lib/python3.8/site-packages/urllib3/connectionpool.py", line 466, in _make_request
    self._validate_conn(conn)
  File "/Users/aming/anaconda3/envs/quant/lib/python3.8/site-packages/urllib3/connectionpool.py", line 1095, in _validate_conn
    conn.connect()
  File "/Users/aming/anaconda3/envs/quant/lib/python3.8/site-packages/urllib3/connection.py", line 730, in connect
    sock_and_verified = _ssl_wrap_socket_and_match_hostname(
  File "/Users/aming/anaconda3/envs/quant/lib/python3.8/site-packages/urllib3/connection.py", line 909, in _ssl_wrap_socket_and_match_hostname
    ssl_sock = ssl_wrap_socket(
  File "/Users/aming/anaconda3/envs/quant/lib/python3.8/site-packages/urllib3/util/ssl_.py", line 469, in ssl_wrap_socket
    ssl_sock = _ssl_wrap_socket_impl(sock, context, tls_in_tls, server_hostname)
  File "/Users/aming/anaconda3/envs/quant/lib/python3.8/site-packages/urllib3/util/ssl_.py", line 513, in _ssl_wrap_socket_impl
    return ssl_context.wrap_socket(sock, server_hostname=server_hostname)
  File "/Users/aming/anaconda3/envs/quant/lib/python3.8/ssl.py", line 500, in wrap_socket
    return self.sslsocket_class._create(
  File "/Users/aming/anaconda3/envs/quant/lib/python3.8/ssl.py", line 1040, in _create
    self.do_handshake()
  File "/Users/aming/anaconda3/envs/quant/lib/python3.8/ssl.py", line 1309, in do_handshake
    self._sslobj.do_handshake()
urllib3.exceptions.ProtocolError: ('Connection aborted.', ConnectionResetError(54, 'Connection reset by peer'))

During handling of the above exception, another exception occurred:

Traceback (most recent call last):
  File "/Users/aming/anaconda3/envs/quant/lib/python3.8/site-packages/cryptofeed/exchange.py", line 103, in symbol_mapping
    data.append(cls.http_sync.read(addr, json=True, uuid=cls.id))
  File "/Users/aming/anaconda3/envs/quant/lib/python3.8/site-packages/cryptofeed/connection.py", line 55, in read
    r = requests.get(address, headers=headers, params=params)
  File "/Users/aming/anaconda3/envs/quant/lib/python3.8/site-packages/requests/api.py", line 73, in get
    return request("get", url, params=params, **kwargs)
  File "/Users/aming/anaconda3/envs/quant/lib/python3.8/site-packages/requests/api.py", line 59, in request
    return session.request(method=method, url=url, **kwargs)
  File "/Users/aming/anaconda3/envs/quant/lib/python3.8/site-packages/requests/sessions.py", line 589, in request
    resp = self.send(prep, **send_kwargs)
  File "/Users/aming/anaconda3/envs/quant/lib/python3.8/site-packages/requests/sessions.py", line 703, in send
    r = adapter.send(request, **kwargs)
  File "/Users/aming/anaconda3/envs/quant/lib/python3.8/site-packages/requests/adapters.py", line 682, in send
    raise ConnectionError(err, request=request)
requests.exceptions.ConnectionError: ('Connection aborted.', ConnectionResetError(54, 'Connection reset by peer'))
2025-09-01 08:38:32,023 : ERROR : COINBASE: Failed to parse symbol information: ('Connection aborted.', ConnectionResetError(54, 'Connection reset by peer'))
Traceback (most recent call last):
  File "/Users/aming/anaconda3/envs/quant/lib/python3.8/site-packages/urllib3/connectionpool.py", line 789, in urlopen
    response = self._make_request(
  File "/Users/aming/anaconda3/envs/quant/lib/python3.8/site-packages/urllib3/connectionpool.py", line 490, in _make_request
    raise new_e
  File "/Users/aming/anaconda3/envs/quant/lib/python3.8/site-packages/urllib3/connectionpool.py", line 466, in _make_request
    self._validate_conn(conn)
  File "/Users/aming/anaconda3/envs/quant/lib/python3.8/site-packages/urllib3/connectionpool.py", line 1095, in _validate_conn
    conn.connect()
  File "/Users/aming/anaconda3/envs/quant/lib/python3.8/site-packages/urllib3/connection.py", line 730, in connect
    sock_and_verified = _ssl_wrap_socket_and_match_hostname(
  File "/Users/aming/anaconda3/envs/quant/lib/python3.8/site-packages/urllib3/connection.py", line 909, in _ssl_wrap_socket_and_match_hostname
    ssl_sock = ssl_wrap_socket(
  File "/Users/aming/anaconda3/envs/quant/lib/python3.8/site-packages/urllib3/util/ssl_.py", line 469, in ssl_wrap_socket
    ssl_sock = _ssl_wrap_socket_impl(sock, context, tls_in_tls, server_hostname)
  File "/Users/aming/anaconda3/envs/quant/lib/python3.8/site-packages/urllib3/util/ssl_.py", line 513, in _ssl_wrap_socket_impl
    return ssl_context.wrap_socket(sock, server_hostname=server_hostname)
  File "/Users/aming/anaconda3/envs/quant/lib/python3.8/ssl.py", line 500, in wrap_socket
    return self.sslsocket_class._create(
  File "/Users/aming/anaconda3/envs/quant/lib/python3.8/ssl.py", line 1040, in _create
    self.do_handshake()
  File "/Users/aming/anaconda3/envs/quant/lib/python3.8/ssl.py", line 1309, in do_handshake
    self._sslobj.do_handshake()
ConnectionResetError: [Errno 54] Connection reset by peer

During handling of the above exception, another exception occurred:

Traceback (most recent call last):
  File "/Users/aming/anaconda3/envs/quant/lib/python3.8/site-packages/requests/adapters.py", line 667, in send
    resp = conn.urlopen(
  File "/Users/aming/anaconda3/envs/quant/lib/python3.8/site-packages/urllib3/connectionpool.py", line 843, in urlopen
    retries = retries.increment(
  File "/Users/aming/anaconda3/envs/quant/lib/python3.8/site-packages/urllib3/util/retry.py", line 474, in increment
    raise reraise(type(error), error, _stacktrace)
  File "/Users/aming/anaconda3/envs/quant/lib/python3.8/site-packages/urllib3/util/util.py", line 38, in reraise
    raise value.with_traceback(tb)
  File "/Users/aming/anaconda3/envs/quant/lib/python3.8/site-packages/urllib3/connectionpool.py", line 789, in urlopen
    response = self._make_request(
  File "/Users/aming/anaconda3/envs/quant/lib/python3.8/site-packages/urllib3/connectionpool.py", line 490, in _make_request
    raise new_e
  File "/Users/aming/anaconda3/envs/quant/lib/python3.8/site-packages/urllib3/connectionpool.py", line 466, in _make_request
    self._validate_conn(conn)
  File "/Users/aming/anaconda3/envs/quant/lib/python3.8/site-packages/urllib3/connectionpool.py", line 1095, in _validate_conn
    conn.connect()
  File "/Users/aming/anaconda3/envs/quant/lib/python3.8/site-packages/urllib3/connection.py", line 730, in connect
    sock_and_verified = _ssl_wrap_socket_and_match_hostname(
  File "/Users/aming/anaconda3/envs/quant/lib/python3.8/site-packages/urllib3/connection.py", line 909, in _ssl_wrap_socket_and_match_hostname
    ssl_sock = ssl_wrap_socket(
  File "/Users/aming/anaconda3/envs/quant/lib/python3.8/site-packages/urllib3/util/ssl_.py", line 469, in ssl_wrap_socket
    ssl_sock = _ssl_wrap_socket_impl(sock, context, tls_in_tls, server_hostname)
  File "/Users/aming/anaconda3/envs/quant/lib/python3.8/site-packages/urllib3/util/ssl_.py", line 513, in _ssl_wrap_socket_impl
    return ssl_context.wrap_socket(sock, server_hostname=server_hostname)
  File "/Users/aming/anaconda3/envs/quant/lib/python3.8/ssl.py", line 500, in wrap_socket
    return self.sslsocket_class._create(
  File "/Users/aming/anaconda3/envs/quant/lib/python3.8/ssl.py", line 1040, in _create
    self.do_handshake()
  File "/Users/aming/anaconda3/envs/quant/lib/python3.8/ssl.py", line 1309, in do_handshake
    self._sslobj.do_handshake()
urllib3.exceptions.ProtocolError: ('Connection aborted.', ConnectionResetError(54, 'Connection reset by peer'))

During handling of the above exception, another exception occurred:

Traceback (most recent call last):
  File "/Users/aming/anaconda3/envs/quant/lib/python3.8/site-packages/cryptofeed/exchange.py", line 103, in symbol_mapping
    data.append(cls.http_sync.read(addr, json=True, uuid=cls.id))
  File "/Users/aming/anaconda3/envs/quant/lib/python3.8/site-packages/cryptofeed/connection.py", line 55, in read
    r = requests.get(address, headers=headers, params=params)
  File "/Users/aming/anaconda3/envs/quant/lib/python3.8/site-packages/requests/api.py", line 73, in get
    return request("get", url, params=params, **kwargs)
  File "/Users/aming/anaconda3/envs/quant/lib/python3.8/site-packages/requests/api.py", line 59, in request
    return session.request(method=method, url=url, **kwargs)
  File "/Users/aming/anaconda3/envs/quant/lib/python3.8/site-packages/requests/sessions.py", line 589, in request
    resp = self.send(prep, **send_kwargs)
  File "/Users/aming/anaconda3/envs/quant/lib/python3.8/site-packages/requests/sessions.py", line 703, in send
    r = adapter.send(request, **kwargs)
  File "/Users/aming/anaconda3/envs/quant/lib/python3.8/site-packages/requests/adapters.py", line 682, in send
    raise ConnectionError(err, request=request)
requests.exceptions.ConnectionError: ('Connection aborted.', ConnectionResetError(54, 'Connection reset by peer'))
2025-09-01 08:41:09,158 : ERROR : COINBASE: Failed to parse symbol information: ('Connection aborted.', ConnectionResetError(54, 'Connection reset by peer'))
Traceback (most recent call last):
  File "/Users/aming/anaconda3/envs/quant/lib/python3.8/site-packages/urllib3/connectionpool.py", line 789, in urlopen
    response = self._make_request(
  File "/Users/aming/anaconda3/envs/quant/lib/python3.8/site-packages/urllib3/connectionpool.py", line 490, in _make_request
    raise new_e
  File "/Users/aming/anaconda3/envs/quant/lib/python3.8/site-packages/urllib3/connectionpool.py", line 466, in _make_request
    self._validate_conn(conn)
  File "/Users/aming/anaconda3/envs/quant/lib/python3.8/site-packages/urllib3/connectionpool.py", line 1095, in _validate_conn
    conn.connect()
  File "/Users/aming/anaconda3/envs/quant/lib/python3.8/site-packages/urllib3/connection.py", line 730, in connect
    sock_and_verified = _ssl_wrap_socket_and_match_hostname(
  File "/Users/aming/anaconda3/envs/quant/lib/python3.8/site-packages/urllib3/connection.py", line 909, in _ssl_wrap_socket_and_match_hostname
    ssl_sock = ssl_wrap_socket(
  File "/Users/aming/anaconda3/envs/quant/lib/python3.8/site-packages/urllib3/util/ssl_.py", line 469, in ssl_wrap_socket
    ssl_sock = _ssl_wrap_socket_impl(sock, context, tls_in_tls, server_hostname)
  File "/Users/aming/anaconda3/envs/quant/lib/python3.8/site-packages/urllib3/util/ssl_.py", line 513, in _ssl_wrap_socket_impl
    return ssl_context.wrap_socket(sock, server_hostname=server_hostname)
  File "/Users/aming/anaconda3/envs/quant/lib/python3.8/ssl.py", line 500, in wrap_socket
    return self.sslsocket_class._create(
  File "/Users/aming/anaconda3/envs/quant/lib/python3.8/ssl.py", line 1040, in _create
    self.do_handshake()
  File "/Users/aming/anaconda3/envs/quant/lib/python3.8/ssl.py", line 1309, in do_handshake
    self._sslobj.do_handshake()
ConnectionResetError: [Errno 54] Connection reset by peer

During handling of the above exception, another exception occurred:

Traceback (most recent call last):
  File "/Users/aming/anaconda3/envs/quant/lib/python3.8/site-packages/requests/adapters.py", line 667, in send
    resp = conn.urlopen(
  File "/Users/aming/anaconda3/envs/quant/lib/python3.8/site-packages/urllib3/connectionpool.py", line 843, in urlopen
    retries = retries.increment(
  File "/Users/aming/anaconda3/envs/quant/lib/python3.8/site-packages/urllib3/util/retry.py", line 474, in increment
    raise reraise(type(error), error, _stacktrace)
  File "/Users/aming/anaconda3/envs/quant/lib/python3.8/site-packages/urllib3/util/util.py", line 38, in reraise
    raise value.with_traceback(tb)
  File "/Users/aming/anaconda3/envs/quant/lib/python3.8/site-packages/urllib3/connectionpool.py", line 789, in urlopen
    response = self._make_request(
  File "/Users/aming/anaconda3/envs/quant/lib/python3.8/site-packages/urllib3/connectionpool.py", line 490, in _make_request
    raise new_e
  File "/Users/aming/anaconda3/envs/quant/lib/python3.8/site-packages/urllib3/connectionpool.py", line 466, in _make_request
    self._validate_conn(conn)
  File "/Users/aming/anaconda3/envs/quant/lib/python3.8/site-packages/urllib3/connectionpool.py", line 1095, in _validate_conn
    conn.connect()
  File "/Users/aming/anaconda3/envs/quant/lib/python3.8/site-packages/urllib3/connection.py", line 730, in connect
    sock_and_verified = _ssl_wrap_socket_and_match_hostname(
  File "/Users/aming/anaconda3/envs/quant/lib/python3.8/site-packages/urllib3/connection.py", line 909, in _ssl_wrap_socket_and_match_hostname
    ssl_sock = ssl_wrap_socket(
  File "/Users/aming/anaconda3/envs/quant/lib/python3.8/site-packages/urllib3/util/ssl_.py", line 469, in ssl_wrap_socket
    ssl_sock = _ssl_wrap_socket_impl(sock, context, tls_in_tls, server_hostname)
  File "/Users/aming/anaconda3/envs/quant/lib/python3.8/site-packages/urllib3/util/ssl_.py", line 513, in _ssl_wrap_socket_impl
    return ssl_context.wrap_socket(sock, server_hostname=server_hostname)
  File "/Users/aming/anaconda3/envs/quant/lib/python3.8/ssl.py", line 500, in wrap_socket
    return self.sslsocket_class._create(
  File "/Users/aming/anaconda3/envs/quant/lib/python3.8/ssl.py", line 1040, in _create
    self.do_handshake()
  File "/Users/aming/anaconda3/envs/quant/lib/python3.8/ssl.py", line 1309, in do_handshake
    self._sslobj.do_handshake()
urllib3.exceptions.ProtocolError: ('Connection aborted.', ConnectionResetError(54, 'Connection reset by peer'))

During handling of the above exception, another exception occurred:

Traceback (most recent call last):
  File "/Users/aming/anaconda3/envs/quant/lib/python3.8/site-packages/cryptofeed/exchange.py", line 103, in symbol_mapping
    data.append(cls.http_sync.read(addr, json=True, uuid=cls.id))
  File "/Users/aming/anaconda3/envs/quant/lib/python3.8/site-packages/cryptofeed/connection.py", line 55, in read
    r = requests.get(address, headers=headers, params=params)
  File "/Users/aming/anaconda3/envs/quant/lib/python3.8/site-packages/requests/api.py", line 73, in get
    return request("get", url, params=params, **kwargs)
  File "/Users/aming/anaconda3/envs/quant/lib/python3.8/site-packages/requests/api.py", line 59, in request
    return session.request(method=method, url=url, **kwargs)
  File "/Users/aming/anaconda3/envs/quant/lib/python3.8/site-packages/requests/sessions.py", line 589, in request
    resp = self.send(prep, **send_kwargs)
  File "/Users/aming/anaconda3/envs/quant/lib/python3.8/site-packages/requests/sessions.py", line 703, in send
    r = adapter.send(request, **kwargs)
  File "/Users/aming/anaconda3/envs/quant/lib/python3.8/site-packages/requests/adapters.py", line 682, in send
    raise ConnectionError(err, request=request)
requests.exceptions.ConnectionError: ('Connection aborted.', ConnectionResetError(54, 'Connection reset by peer'))
2025-09-01 08:46:43,094 : ERROR : COINBASE: Failed to parse symbol information: 503 Server Error: Service Unavailable for url: https://api.pro.coinbase.com/products
Traceback (most recent call last):
  File "/Users/aming/anaconda3/envs/quant/lib/python3.8/site-packages/cryptofeed/exchange.py", line 103, in symbol_mapping
    data.append(cls.http_sync.read(addr, json=True, uuid=cls.id))
  File "/Users/aming/anaconda3/envs/quant/lib/python3.8/site-packages/cryptofeed/connection.py", line 56, in read
    return self.process_response(r, address, json=json, text=text, uuid=uuid)
  File "/Users/aming/anaconda3/envs/quant/lib/python3.8/site-packages/cryptofeed/connection.py", line 46, in process_response
    r.raise_for_status()
  File "/Users/aming/anaconda3/envs/quant/lib/python3.8/site-packages/requests/models.py", line 1024, in raise_for_status
    raise HTTPError(http_error_msg, response=self)
requests.exceptions.HTTPError: 503 Server Error: Service Unavailable for url: https://api.pro.coinbase.com/products
2025-09-01 08:49:38,547 : ERROR : BINANCE_FUTURES: Failed to parse symbol information: ('Connection aborted.', ConnectionResetError(54, 'Connection reset by peer'))
Traceback (most recent call last):
  File "/Users/aming/anaconda3/envs/quant/lib/python3.8/site-packages/urllib3/connectionpool.py", line 789, in urlopen
    response = self._make_request(
  File "/Users/aming/anaconda3/envs/quant/lib/python3.8/site-packages/urllib3/connectionpool.py", line 490, in _make_request
    raise new_e
  File "/Users/aming/anaconda3/envs/quant/lib/python3.8/site-packages/urllib3/connectionpool.py", line 466, in _make_request
    self._validate_conn(conn)
  File "/Users/aming/anaconda3/envs/quant/lib/python3.8/site-packages/urllib3/connectionpool.py", line 1095, in _validate_conn
    conn.connect()
  File "/Users/aming/anaconda3/envs/quant/lib/python3.8/site-packages/urllib3/connection.py", line 730, in connect
    sock_and_verified = _ssl_wrap_socket_and_match_hostname(
  File "/Users/aming/anaconda3/envs/quant/lib/python3.8/site-packages/urllib3/connection.py", line 909, in _ssl_wrap_socket_and_match_hostname
    ssl_sock = ssl_wrap_socket(
  File "/Users/aming/anaconda3/envs/quant/lib/python3.8/site-packages/urllib3/util/ssl_.py", line 469, in ssl_wrap_socket
    ssl_sock = _ssl_wrap_socket_impl(sock, context, tls_in_tls, server_hostname)
  File "/Users/aming/anaconda3/envs/quant/lib/python3.8/site-packages/urllib3/util/ssl_.py", line 513, in _ssl_wrap_socket_impl
    return ssl_context.wrap_socket(sock, server_hostname=server_hostname)
  File "/Users/aming/anaconda3/envs/quant/lib/python3.8/ssl.py", line 500, in wrap_socket
    return self.sslsocket_class._create(
  File "/Users/aming/anaconda3/envs/quant/lib/python3.8/ssl.py", line 1040, in _create
    self.do_handshake()
  File "/Users/aming/anaconda3/envs/quant/lib/python3.8/ssl.py", line 1309, in do_handshake
    self._sslobj.do_handshake()
ConnectionResetError: [Errno 54] Connection reset by peer

During handling of the above exception, another exception occurred:

Traceback (most recent call last):
  File "/Users/aming/anaconda3/envs/quant/lib/python3.8/site-packages/requests/adapters.py", line 667, in send
    resp = conn.urlopen(
  File "/Users/aming/anaconda3/envs/quant/lib/python3.8/site-packages/urllib3/connectionpool.py", line 843, in urlopen
    retries = retries.increment(
  File "/Users/aming/anaconda3/envs/quant/lib/python3.8/site-packages/urllib3/util/retry.py", line 474, in increment
    raise reraise(type(error), error, _stacktrace)
  File "/Users/aming/anaconda3/envs/quant/lib/python3.8/site-packages/urllib3/util/util.py", line 38, in reraise
    raise value.with_traceback(tb)
  File "/Users/aming/anaconda3/envs/quant/lib/python3.8/site-packages/urllib3/connectionpool.py", line 789, in urlopen
    response = self._make_request(
  File "/Users/aming/anaconda3/envs/quant/lib/python3.8/site-packages/urllib3/connectionpool.py", line 490, in _make_request
    raise new_e
  File "/Users/aming/anaconda3/envs/quant/lib/python3.8/site-packages/urllib3/connectionpool.py", line 466, in _make_request
    self._validate_conn(conn)
  File "/Users/aming/anaconda3/envs/quant/lib/python3.8/site-packages/urllib3/connectionpool.py", line 1095, in _validate_conn
    conn.connect()
  File "/Users/aming/anaconda3/envs/quant/lib/python3.8/site-packages/urllib3/connection.py", line 730, in connect
    sock_and_verified = _ssl_wrap_socket_and_match_hostname(
  File "/Users/aming/anaconda3/envs/quant/lib/python3.8/site-packages/urllib3/connection.py", line 909, in _ssl_wrap_socket_and_match_hostname
    ssl_sock = ssl_wrap_socket(
  File "/Users/aming/anaconda3/envs/quant/lib/python3.8/site-packages/urllib3/util/ssl_.py", line 469, in ssl_wrap_socket
    ssl_sock = _ssl_wrap_socket_impl(sock, context, tls_in_tls, server_hostname)
  File "/Users/aming/anaconda3/envs/quant/lib/python3.8/site-packages/urllib3/util/ssl_.py", line 513, in _ssl_wrap_socket_impl
    return ssl_context.wrap_socket(sock, server_hostname=server_hostname)
  File "/Users/aming/anaconda3/envs/quant/lib/python3.8/ssl.py", line 500, in wrap_socket
    return self.sslsocket_class._create(
  File "/Users/aming/anaconda3/envs/quant/lib/python3.8/ssl.py", line 1040, in _create
    self.do_handshake()
  File "/Users/aming/anaconda3/envs/quant/lib/python3.8/ssl.py", line 1309, in do_handshake
    self._sslobj.do_handshake()
urllib3.exceptions.ProtocolError: ('Connection aborted.', ConnectionResetError(54, 'Connection reset by peer'))

During handling of the above exception, another exception occurred:

Traceback (most recent call last):
  File "/Users/aming/anaconda3/envs/quant/lib/python3.8/site-packages/cryptofeed/exchange.py", line 103, in symbol_mapping
    data.append(cls.http_sync.read(addr, json=True, uuid=cls.id))
  File "/Users/aming/anaconda3/envs/quant/lib/python3.8/site-packages/cryptofeed/connection.py", line 55, in read
    r = requests.get(address, headers=headers, params=params)
  File "/Users/aming/anaconda3/envs/quant/lib/python3.8/site-packages/requests/api.py", line 73, in get
    return request("get", url, params=params, **kwargs)
  File "/Users/aming/anaconda3/envs/quant/lib/python3.8/site-packages/requests/api.py", line 59, in request
    return session.request(method=method, url=url, **kwargs)
  File "/Users/aming/anaconda3/envs/quant/lib/python3.8/site-packages/requests/sessions.py", line 589, in request
    resp = self.send(prep, **send_kwargs)
  File "/Users/aming/anaconda3/envs/quant/lib/python3.8/site-packages/requests/sessions.py", line 703, in send
    r = adapter.send(request, **kwargs)
  File "/Users/aming/anaconda3/envs/quant/lib/python3.8/site-packages/requests/adapters.py", line 682, in send
    raise ConnectionError(err, request=request)
requests.exceptions.ConnectionError: ('Connection aborted.', ConnectionResetError(54, 'Connection reset by peer'))
2025-09-01 08:53:48,902 : ERROR : BINANCE_FUTURES: Failed to parse symbol information: ('Connection aborted.', ConnectionResetError(54, 'Connection reset by peer'))
Traceback (most recent call last):
  File "/Users/aming/anaconda3/envs/quant/lib/python3.8/site-packages/urllib3/connectionpool.py", line 789, in urlopen
    response = self._make_request(
  File "/Users/aming/anaconda3/envs/quant/lib/python3.8/site-packages/urllib3/connectionpool.py", line 490, in _make_request
    raise new_e
  File "/Users/aming/anaconda3/envs/quant/lib/python3.8/site-packages/urllib3/connectionpool.py", line 466, in _make_request
    self._validate_conn(conn)
  File "/Users/aming/anaconda3/envs/quant/lib/python3.8/site-packages/urllib3/connectionpool.py", line 1095, in _validate_conn
    conn.connect()
  File "/Users/aming/anaconda3/envs/quant/lib/python3.8/site-packages/urllib3/connection.py", line 730, in connect
    sock_and_verified = _ssl_wrap_socket_and_match_hostname(
  File "/Users/aming/anaconda3/envs/quant/lib/python3.8/site-packages/urllib3/connection.py", line 909, in _ssl_wrap_socket_and_match_hostname
    ssl_sock = ssl_wrap_socket(
  File "/Users/aming/anaconda3/envs/quant/lib/python3.8/site-packages/urllib3/util/ssl_.py", line 469, in ssl_wrap_socket
    ssl_sock = _ssl_wrap_socket_impl(sock, context, tls_in_tls, server_hostname)
  File "/Users/aming/anaconda3/envs/quant/lib/python3.8/site-packages/urllib3/util/ssl_.py", line 513, in _ssl_wrap_socket_impl
    return ssl_context.wrap_socket(sock, server_hostname=server_hostname)
  File "/Users/aming/anaconda3/envs/quant/lib/python3.8/ssl.py", line 500, in wrap_socket
    return self.sslsocket_class._create(
  File "/Users/aming/anaconda3/envs/quant/lib/python3.8/ssl.py", line 1040, in _create
    self.do_handshake()
  File "/Users/aming/anaconda3/envs/quant/lib/python3.8/ssl.py", line 1309, in do_handshake
    self._sslobj.do_handshake()
ConnectionResetError: [Errno 54] Connection reset by peer

During handling of the above exception, another exception occurred:

Traceback (most recent call last):
  File "/Users/aming/anaconda3/envs/quant/lib/python3.8/site-packages/requests/adapters.py", line 667, in send
    resp = conn.urlopen(
  File "/Users/aming/anaconda3/envs/quant/lib/python3.8/site-packages/urllib3/connectionpool.py", line 843, in urlopen
    retries = retries.increment(
  File "/Users/aming/anaconda3/envs/quant/lib/python3.8/site-packages/urllib3/util/retry.py", line 474, in increment
    raise reraise(type(error), error, _stacktrace)
  File "/Users/aming/anaconda3/envs/quant/lib/python3.8/site-packages/urllib3/util/util.py", line 38, in reraise
    raise value.with_traceback(tb)
  File "/Users/aming/anaconda3/envs/quant/lib/python3.8/site-packages/urllib3/connectionpool.py", line 789, in urlopen
    response = self._make_request(
  File "/Users/aming/anaconda3/envs/quant/lib/python3.8/site-packages/urllib3/connectionpool.py", line 490, in _make_request
    raise new_e
  File "/Users/aming/anaconda3/envs/quant/lib/python3.8/site-packages/urllib3/connectionpool.py", line 466, in _make_request
    self._validate_conn(conn)
  File "/Users/aming/anaconda3/envs/quant/lib/python3.8/site-packages/urllib3/connectionpool.py", line 1095, in _validate_conn
    conn.connect()
  File "/Users/aming/anaconda3/envs/quant/lib/python3.8/site-packages/urllib3/connection.py", line 730, in connect
    sock_and_verified = _ssl_wrap_socket_and_match_hostname(
  File "/Users/aming/anaconda3/envs/quant/lib/python3.8/site-packages/urllib3/connection.py", line 909, in _ssl_wrap_socket_and_match_hostname
    ssl_sock = ssl_wrap_socket(
  File "/Users/aming/anaconda3/envs/quant/lib/python3.8/site-packages/urllib3/util/ssl_.py", line 469, in ssl_wrap_socket
    ssl_sock = _ssl_wrap_socket_impl(sock, context, tls_in_tls, server_hostname)
  File "/Users/aming/anaconda3/envs/quant/lib/python3.8/site-packages/urllib3/util/ssl_.py", line 513, in _ssl_wrap_socket_impl
    return ssl_context.wrap_socket(sock, server_hostname=server_hostname)
  File "/Users/aming/anaconda3/envs/quant/lib/python3.8/ssl.py", line 500, in wrap_socket
    return self.sslsocket_class._create(
  File "/Users/aming/anaconda3/envs/quant/lib/python3.8/ssl.py", line 1040, in _create
    self.do_handshake()
  File "/Users/aming/anaconda3/envs/quant/lib/python3.8/ssl.py", line 1309, in do_handshake
    self._sslobj.do_handshake()
urllib3.exceptions.ProtocolError: ('Connection aborted.', ConnectionResetError(54, 'Connection reset by peer'))

During handling of the above exception, another exception occurred:

Traceback (most recent call last):
  File "/Users/aming/anaconda3/envs/quant/lib/python3.8/site-packages/cryptofeed/exchange.py", line 103, in symbol_mapping
    data.append(cls.http_sync.read(addr, json=True, uuid=cls.id))
  File "/Users/aming/anaconda3/envs/quant/lib/python3.8/site-packages/cryptofeed/connection.py", line 55, in read
    r = requests.get(address, headers=headers, params=params)
  File "/Users/aming/anaconda3/envs/quant/lib/python3.8/site-packages/requests/api.py", line 73, in get
    return request("get", url, params=params, **kwargs)
  File "/Users/aming/anaconda3/envs/quant/lib/python3.8/site-packages/requests/api.py", line 59, in request
    return session.request(method=method, url=url, **kwargs)
  File "/Users/aming/anaconda3/envs/quant/lib/python3.8/site-packages/requests/sessions.py", line 589, in request
    resp = self.send(prep, **send_kwargs)
  File "/Users/aming/anaconda3/envs/quant/lib/python3.8/site-packages/requests/sessions.py", line 703, in send
    r = adapter.send(request, **kwargs)
  File "/Users/aming/anaconda3/envs/quant/lib/python3.8/site-packages/requests/adapters.py", line 682, in send
    raise ConnectionError(err, request=request)
requests.exceptions.ConnectionError: ('Connection aborted.', ConnectionResetError(54, 'Connection reset by peer'))
2025-09-01 09:17:25,459 : WARNING : BINANCE_FUTURES.ws.1: encountered connection issue [Errno 54] Connection reset by peer - reconnecting in 1.0 seconds...
Traceback (most recent call last):
  File "/Users/aming/anaconda3/envs/quant/lib/python3.8/site-packages/cryptofeed/connection_handler.py", line 59, in _create_connection
    async with self.conn.connect() as connection:
  File "/Users/aming/anaconda3/envs/quant/lib/python3.8/contextlib.py", line 171, in __aenter__
    return await self.gen.__anext__()
  File "/Users/aming/anaconda3/envs/quant/lib/python3.8/site-packages/cryptofeed/connection.py", line 104, in connect
    await self._open()
  File "/Users/aming/anaconda3/envs/quant/lib/python3.8/site-packages/cryptofeed/connection.py", line 318, in _open
    self.conn = await websockets.connect(self.address, **self.ws_kwargs)
  File "/Users/aming/anaconda3/envs/quant/lib/python3.8/site-packages/websockets/legacy/client.py", line 654, in __await_impl__
    _transport, protocol = await self._create_connection()
  File "uvloop/loop.pyx", line 2088, in create_connection
  File "uvloop/loop.pyx", line 2083, in uvloop.loop.Loop.create_connection
ConnectionResetError: [Errno 54] Connection reset by peer
2025-09-01 09:17:26,581 : WARNING : BINANCE_FUTURES.ws.1: encountered connection issue [Errno 54] Connection reset by peer - reconnecting in 2.0 seconds...
Traceback (most recent call last):
  File "/Users/aming/anaconda3/envs/quant/lib/python3.8/site-packages/cryptofeed/connection_handler.py", line 59, in _create_connection
    async with self.conn.connect() as connection:
  File "/Users/aming/anaconda3/envs/quant/lib/python3.8/contextlib.py", line 171, in __aenter__
    return await self.gen.__anext__()
  File "/Users/aming/anaconda3/envs/quant/lib/python3.8/site-packages/cryptofeed/connection.py", line 104, in connect
    await self._open()
  File "/Users/aming/anaconda3/envs/quant/lib/python3.8/site-packages/cryptofeed/connection.py", line 318, in _open
    self.conn = await websockets.connect(self.address, **self.ws_kwargs)
  File "/Users/aming/anaconda3/envs/quant/lib/python3.8/site-packages/websockets/legacy/client.py", line 654, in __await_impl__
    _transport, protocol = await self._create_connection()
  File "uvloop/loop.pyx", line 2088, in create_connection
  File "uvloop/loop.pyx", line 2083, in uvloop.loop.Loop.create_connection
ConnectionResetError: [Errno 54] Connection reset by peer
2025-09-01 09:17:28,706 : WARNING : BINANCE_FUTURES.ws.1: encountered connection issue [Errno 54] Connection reset by peer - reconnecting in 4.0 seconds...
Traceback (most recent call last):
  File "/Users/aming/anaconda3/envs/quant/lib/python3.8/site-packages/cryptofeed/connection_handler.py", line 59, in _create_connection
    async with self.conn.connect() as connection:
  File "/Users/aming/anaconda3/envs/quant/lib/python3.8/contextlib.py", line 171, in __aenter__
    return await self.gen.__anext__()
  File "/Users/aming/anaconda3/envs/quant/lib/python3.8/site-packages/cryptofeed/connection.py", line 104, in connect
    await self._open()
  File "/Users/aming/anaconda3/envs/quant/lib/python3.8/site-packages/cryptofeed/connection.py", line 318, in _open
    self.conn = await websockets.connect(self.address, **self.ws_kwargs)
  File "/Users/aming/anaconda3/envs/quant/lib/python3.8/site-packages/websockets/legacy/client.py", line 654, in __await_impl__
    _transport, protocol = await self._create_connection()
  File "uvloop/loop.pyx", line 2088, in create_connection
  File "uvloop/loop.pyx", line 2083, in uvloop.loop.Loop.create_connection
ConnectionResetError: [Errno 54] Connection reset by peer
2025-09-01 09:17:32,813 : WARNING : BINANCE_FUTURES.ws.1: encountered connection issue [Errno 54] Connection reset by peer - reconnecting in 8.0 seconds...
Traceback (most recent call last):
  File "/Users/aming/anaconda3/envs/quant/lib/python3.8/site-packages/cryptofeed/connection_handler.py", line 59, in _create_connection
    async with self.conn.connect() as connection:
  File "/Users/aming/anaconda3/envs/quant/lib/python3.8/contextlib.py", line 171, in __aenter__
    return await self.gen.__anext__()
  File "/Users/aming/anaconda3/envs/quant/lib/python3.8/site-packages/cryptofeed/connection.py", line 104, in connect
    await self._open()
  File "/Users/aming/anaconda3/envs/quant/lib/python3.8/site-packages/cryptofeed/connection.py", line 318, in _open
    self.conn = await websockets.connect(self.address, **self.ws_kwargs)
  File "/Users/aming/anaconda3/envs/quant/lib/python3.8/site-packages/websockets/legacy/client.py", line 654, in __await_impl__
    _transport, protocol = await self._create_connection()
  File "uvloop/loop.pyx", line 2088, in create_connection
  File "uvloop/loop.pyx", line 2083, in uvloop.loop.Loop.create_connection
ConnectionResetError: [Errno 54] Connection reset by peer
2025-09-01 09:17:40,930 : WARNING : BINANCE_FUTURES.ws.1: encountered connection issue [Errno 54] Connection reset by peer - reconnecting in 16.0 seconds...
Traceback (most recent call last):
  File "/Users/aming/anaconda3/envs/quant/lib/python3.8/site-packages/cryptofeed/connection_handler.py", line 59, in _create_connection
    async with self.conn.connect() as connection:
  File "/Users/aming/anaconda3/envs/quant/lib/python3.8/contextlib.py", line 171, in __aenter__
    return await self.gen.__anext__()
  File "/Users/aming/anaconda3/envs/quant/lib/python3.8/site-packages/cryptofeed/connection.py", line 104, in connect
    await self._open()
  File "/Users/aming/anaconda3/envs/quant/lib/python3.8/site-packages/cryptofeed/connection.py", line 318, in _open
    self.conn = await websockets.connect(self.address, **self.ws_kwargs)
  File "/Users/aming/anaconda3/envs/quant/lib/python3.8/site-packages/websockets/legacy/client.py", line 654, in __await_impl__
    _transport, protocol = await self._create_connection()
  File "uvloop/loop.pyx", line 2088, in create_connection
  File "uvloop/loop.pyx", line 2083, in uvloop.loop.Loop.create_connection
ConnectionResetError: [Errno 54] Connection reset by peer
2025-09-01 09:18:01,723 : WARNING : BINANCE_FUTURES.ws.1: encountered connection issue [Errno 54] Connection reset by peer - reconnecting in 1.0 seconds...
Traceback (most recent call last):
  File "/Users/aming/anaconda3/envs/quant/lib/python3.8/site-packages/cryptofeed/connection_handler.py", line 59, in _create_connection
    async with self.conn.connect() as connection:
  File "/Users/aming/anaconda3/envs/quant/lib/python3.8/contextlib.py", line 171, in __aenter__
    return await self.gen.__anext__()
  File "/Users/aming/anaconda3/envs/quant/lib/python3.8/site-packages/cryptofeed/connection.py", line 104, in connect
    await self._open()
  File "/Users/aming/anaconda3/envs/quant/lib/python3.8/site-packages/cryptofeed/connection.py", line 318, in _open
    self.conn = await websockets.connect(self.address, **self.ws_kwargs)
  File "/Users/aming/anaconda3/envs/quant/lib/python3.8/site-packages/websockets/legacy/client.py", line 654, in __await_impl__
    _transport, protocol = await self._create_connection()
  File "uvloop/loop.pyx", line 2088, in create_connection
  File "uvloop/loop.pyx", line 2083, in uvloop.loop.Loop.create_connection
ConnectionResetError: [Errno 54] Connection reset by peer
2025-09-01 09:18:02,848 : WARNING : BINANCE_FUTURES.ws.1: encountered connection issue [Errno 54] Connection reset by peer - reconnecting in 2.0 seconds...
Traceback (most recent call last):
  File "/Users/aming/anaconda3/envs/quant/lib/python3.8/site-packages/cryptofeed/connection_handler.py", line 59, in _create_connection
    async with self.conn.connect() as connection:
  File "/Users/aming/anaconda3/envs/quant/lib/python3.8/contextlib.py", line 171, in __aenter__
    return await self.gen.__anext__()
  File "/Users/aming/anaconda3/envs/quant/lib/python3.8/site-packages/cryptofeed/connection.py", line 104, in connect
    await self._open()
  File "/Users/aming/anaconda3/envs/quant/lib/python3.8/site-packages/cryptofeed/connection.py", line 318, in _open
    self.conn = await websockets.connect(self.address, **self.ws_kwargs)
  File "/Users/aming/anaconda3/envs/quant/lib/python3.8/site-packages/websockets/legacy/client.py", line 654, in __await_impl__
    _transport, protocol = await self._create_connection()
  File "uvloop/loop.pyx", line 2088, in create_connection
  File "uvloop/loop.pyx", line 2083, in uvloop.loop.Loop.create_connection
ConnectionResetError: [Errno 54] Connection reset by peer
2025-09-01 09:18:04,966 : WARNING : BINANCE_FUTURES.ws.1: encountered connection issue [Errno 54] Connection reset by peer - reconnecting in 4.0 seconds...
Traceback (most recent call last):
  File "/Users/aming/anaconda3/envs/quant/lib/python3.8/site-packages/cryptofeed/connection_handler.py", line 59, in _create_connection
    async with self.conn.connect() as connection:
  File "/Users/aming/anaconda3/envs/quant/lib/python3.8/contextlib.py", line 171, in __aenter__
    return await self.gen.__anext__()
  File "/Users/aming/anaconda3/envs/quant/lib/python3.8/site-packages/cryptofeed/connection.py", line 104, in connect
    await self._open()
  File "/Users/aming/anaconda3/envs/quant/lib/python3.8/site-packages/cryptofeed/connection.py", line 318, in _open
    self.conn = await websockets.connect(self.address, **self.ws_kwargs)
  File "/Users/aming/anaconda3/envs/quant/lib/python3.8/site-packages/websockets/legacy/client.py", line 654, in __await_impl__
    _transport, protocol = await self._create_connection()
  File "uvloop/loop.pyx", line 2088, in create_connection
  File "uvloop/loop.pyx", line 2083, in uvloop.loop.Loop.create_connection
ConnectionResetError: [Errno 54] Connection reset by peer
2025-09-01 09:18:09,074 : WARNING : BINANCE_FUTURES.ws.1: encountered connection issue [Errno 54] Connection reset by peer - reconnecting in 8.0 seconds...
Traceback (most recent call last):
  File "/Users/aming/anaconda3/envs/quant/lib/python3.8/site-packages/cryptofeed/connection_handler.py", line 59, in _create_connection
    async with self.conn.connect() as connection:
  File "/Users/aming/anaconda3/envs/quant/lib/python3.8/contextlib.py", line 171, in __aenter__
    return await self.gen.__anext__()
  File "/Users/aming/anaconda3/envs/quant/lib/python3.8/site-packages/cryptofeed/connection.py", line 104, in connect
    await self._open()
  File "/Users/aming/anaconda3/envs/quant/lib/python3.8/site-packages/cryptofeed/connection.py", line 318, in _open
    self.conn = await websockets.connect(self.address, **self.ws_kwargs)
  File "/Users/aming/anaconda3/envs/quant/lib/python3.8/site-packages/websockets/legacy/client.py", line 654, in __await_impl__
    _transport, protocol = await self._create_connection()
  File "uvloop/loop.pyx", line 2088, in create_connection
  File "uvloop/loop.pyx", line 2083, in uvloop.loop.Loop.create_connection
ConnectionResetError: [Errno 54] Connection reset by peer
2025-09-01 09:18:17,184 : WARNING : BINANCE_FUTURES.ws.1: encountered connection issue [Errno 54] Connection reset by peer - reconnecting in 16.0 seconds...
Traceback (most recent call last):
  File "/Users/aming/anaconda3/envs/quant/lib/python3.8/site-packages/cryptofeed/connection_handler.py", line 59, in _create_connection
    async with self.conn.connect() as connection:
  File "/Users/aming/anaconda3/envs/quant/lib/python3.8/contextlib.py", line 171, in __aenter__
    return await self.gen.__anext__()
  File "/Users/aming/anaconda3/envs/quant/lib/python3.8/site-packages/cryptofeed/connection.py", line 104, in connect
    await self._open()
  File "/Users/aming/anaconda3/envs/quant/lib/python3.8/site-packages/cryptofeed/connection.py", line 318, in _open
    self.conn = await websockets.connect(self.address, **self.ws_kwargs)
  File "/Users/aming/anaconda3/envs/quant/lib/python3.8/site-packages/websockets/legacy/client.py", line 654, in __await_impl__
    _transport, protocol = await self._create_connection()
  File "uvloop/loop.pyx", line 2088, in create_connection
  File "uvloop/loop.pyx", line 2083, in uvloop.loop.Loop.create_connection
ConnectionResetError: [Errno 54] Connection reset by peer
2025-09-01 09:18:33,305 : WARNING : BINANCE_FUTURES.ws.1: encountered connection issue [Errno 54] Connection reset by peer - reconnecting in 32.0 seconds...
Traceback (most recent call last):
  File "/Users/aming/anaconda3/envs/quant/lib/python3.8/site-packages/cryptofeed/connection_handler.py", line 59, in _create_connection
    async with self.conn.connect() as connection:
  File "/Users/aming/anaconda3/envs/quant/lib/python3.8/contextlib.py", line 171, in __aenter__
    return await self.gen.__anext__()
  File "/Users/aming/anaconda3/envs/quant/lib/python3.8/site-packages/cryptofeed/connection.py", line 104, in connect
    await self._open()
  File "/Users/aming/anaconda3/envs/quant/lib/python3.8/site-packages/cryptofeed/connection.py", line 318, in _open
    self.conn = await websockets.connect(self.address, **self.ws_kwargs)
  File "/Users/aming/anaconda3/envs/quant/lib/python3.8/site-packages/websockets/legacy/client.py", line 654, in __await_impl__
    _transport, protocol = await self._create_connection()
  File "uvloop/loop.pyx", line 2088, in create_connection
  File "uvloop/loop.pyx", line 2083, in uvloop.loop.Loop.create_connection
ConnectionResetError: [Errno 54] Connection reset by peer
2025-09-01 09:19:05,433 : WARNING : BINANCE_FUTURES.ws.1: encountered connection issue [Errno 54] Connection reset by peer - reconnecting in 64.0 seconds...
Traceback (most recent call last):
  File "/Users/aming/anaconda3/envs/quant/lib/python3.8/site-packages/cryptofeed/connection_handler.py", line 59, in _create_connection
    async with self.conn.connect() as connection:
  File "/Users/aming/anaconda3/envs/quant/lib/python3.8/contextlib.py", line 171, in __aenter__
    return await self.gen.__anext__()
  File "/Users/aming/anaconda3/envs/quant/lib/python3.8/site-packages/cryptofeed/connection.py", line 104, in connect
    await self._open()
  File "/Users/aming/anaconda3/envs/quant/lib/python3.8/site-packages/cryptofeed/connection.py", line 318, in _open
    self.conn = await websockets.connect(self.address, **self.ws_kwargs)
  File "/Users/aming/anaconda3/envs/quant/lib/python3.8/site-packages/websockets/legacy/client.py", line 654, in __await_impl__
    _transport, protocol = await self._create_connection()
  File "uvloop/loop.pyx", line 2088, in create_connection
  File "uvloop/loop.pyx", line 2083, in uvloop.loop.Loop.create_connection
ConnectionResetError: [Errno 54] Connection reset by peer
2025-09-01 09:29:26,925 : WARNING : BINANCE_FUTURES.ws.1: encountered connection issue [Errno 54] Connection reset by peer - reconnecting in 128.0 seconds...
Traceback (most recent call last):
  File "/Users/aming/anaconda3/envs/quant/lib/python3.8/site-packages/cryptofeed/connection_handler.py", line 59, in _create_connection
    async with self.conn.connect() as connection:
  File "/Users/aming/anaconda3/envs/quant/lib/python3.8/contextlib.py", line 171, in __aenter__
    return await self.gen.__anext__()
  File "/Users/aming/anaconda3/envs/quant/lib/python3.8/site-packages/cryptofeed/connection.py", line 104, in connect
    await self._open()
  File "/Users/aming/anaconda3/envs/quant/lib/python3.8/site-packages/cryptofeed/connection.py", line 318, in _open
    self.conn = await websockets.connect(self.address, **self.ws_kwargs)
  File "/Users/aming/anaconda3/envs/quant/lib/python3.8/site-packages/websockets/legacy/client.py", line 654, in __await_impl__
    _transport, protocol = await self._create_connection()
  File "uvloop/loop.pyx", line 2088, in create_connection
  File "uvloop/loop.pyx", line 2083, in uvloop.loop.Loop.create_connection
ConnectionResetError: [Errno 54] Connection reset by peer
2025-09-01 09:38:14,400 : ERROR : FH: Unhandled RuntimeError('This event loop is already running') - shutting down
Traceback (most recent call last):
  File "/Users/aming/anaconda3/envs/quant/lib/python3.8/site-packages/cryptofeed/feedhandler.py", line 151, in run
    loop.run_forever()
  File "/Users/aming/anaconda3/envs/quant/lib/python3.8/asyncio/base_events.py", line 560, in run_forever
    self._check_running()
  File "/Users/aming/anaconda3/envs/quant/lib/python3.8/asyncio/base_events.py", line 552, in _check_running
    raise RuntimeError('This event loop is already running')
RuntimeError: This event loop is already running
2025-09-01 09:38:35,960 : WARNING : BINANCE_FUTURES.ws.1: encountered connection issue [Errno 54] Connection reset by peer - reconnecting in 1.0 seconds...
Traceback (most recent call last):
  File "/Users/aming/anaconda3/envs/quant/lib/python3.8/site-packages/cryptofeed/connection_handler.py", line 59, in _create_connection
    async with self.conn.connect() as connection:
  File "/Users/aming/anaconda3/envs/quant/lib/python3.8/contextlib.py", line 171, in __aenter__
    return await self.gen.__anext__()
  File "/Users/aming/anaconda3/envs/quant/lib/python3.8/site-packages/cryptofeed/connection.py", line 104, in connect
    await self._open()
  File "/Users/aming/anaconda3/envs/quant/lib/python3.8/site-packages/cryptofeed/connection.py", line 318, in _open
    self.conn = await websockets.connect(self.address, **self.ws_kwargs)
  File "/Users/aming/anaconda3/envs/quant/lib/python3.8/site-packages/websockets/legacy/client.py", line 654, in __await_impl__
    _transport, protocol = await self._create_connection()
  File "uvloop/loop.pyx", line 2088, in create_connection
  File "uvloop/loop.pyx", line 2083, in uvloop.loop.Loop.create_connection
ConnectionResetError: [Errno 54] Connection reset by peer
2025-09-01 09:38:37,066 : WARNING : BINANCE_FUTURES.ws.1: encountered connection issue [Errno 54] Connection reset by peer - reconnecting in 2.0 seconds...
Traceback (most recent call last):
  File "/Users/aming/anaconda3/envs/quant/lib/python3.8/site-packages/cryptofeed/connection_handler.py", line 59, in _create_connection
    async with self.conn.connect() as connection:
  File "/Users/aming/anaconda3/envs/quant/lib/python3.8/contextlib.py", line 171, in __aenter__
    return await self.gen.__anext__()
  File "/Users/aming/anaconda3/envs/quant/lib/python3.8/site-packages/cryptofeed/connection.py", line 104, in connect
    await self._open()
  File "/Users/aming/anaconda3/envs/quant/lib/python3.8/site-packages/cryptofeed/connection.py", line 318, in _open
    self.conn = await websockets.connect(self.address, **self.ws_kwargs)
  File "/Users/aming/anaconda3/envs/quant/lib/python3.8/site-packages/websockets/legacy/client.py", line 654, in __await_impl__
    _transport, protocol = await self._create_connection()
  File "uvloop/loop.pyx", line 2088, in create_connection
  File "uvloop/loop.pyx", line 2083, in uvloop.loop.Loop.create_connection
ConnectionResetError: [Errno 54] Connection reset by peer
2025-09-01 09:38:39,177 : WARNING : BINANCE_FUTURES.ws.1: encountered connection issue [Errno 54] Connection reset by peer - reconnecting in 4.0 seconds...
Traceback (most recent call last):
  File "/Users/aming/anaconda3/envs/quant/lib/python3.8/site-packages/cryptofeed/connection_handler.py", line 59, in _create_connection
    async with self.conn.connect() as connection:
  File "/Users/aming/anaconda3/envs/quant/lib/python3.8/contextlib.py", line 171, in __aenter__
    return await self.gen.__anext__()
  File "/Users/aming/anaconda3/envs/quant/lib/python3.8/site-packages/cryptofeed/connection.py", line 104, in connect
    await self._open()
  File "/Users/aming/anaconda3/envs/quant/lib/python3.8/site-packages/cryptofeed/connection.py", line 318, in _open
    self.conn = await websockets.connect(self.address, **self.ws_kwargs)
  File "/Users/aming/anaconda3/envs/quant/lib/python3.8/site-packages/websockets/legacy/client.py", line 654, in __await_impl__
    _transport, protocol = await self._create_connection()
  File "uvloop/loop.pyx", line 2088, in create_connection
  File "uvloop/loop.pyx", line 2083, in uvloop.loop.Loop.create_connection
ConnectionResetError: [Errno 54] Connection reset by peer
2025-09-01 09:38:43,289 : WARNING : BINANCE_FUTURES.ws.1: encountered connection issue [Errno 54] Connection reset by peer - reconnecting in 8.0 seconds...
Traceback (most recent call last):
  File "/Users/aming/anaconda3/envs/quant/lib/python3.8/site-packages/cryptofeed/connection_handler.py", line 59, in _create_connection
    async with self.conn.connect() as connection:
  File "/Users/aming/anaconda3/envs/quant/lib/python3.8/contextlib.py", line 171, in __aenter__
    return await self.gen.__anext__()
  File "/Users/aming/anaconda3/envs/quant/lib/python3.8/site-packages/cryptofeed/connection.py", line 104, in connect
    await self._open()
  File "/Users/aming/anaconda3/envs/quant/lib/python3.8/site-packages/cryptofeed/connection.py", line 318, in _open
    self.conn = await websockets.connect(self.address, **self.ws_kwargs)
  File "/Users/aming/anaconda3/envs/quant/lib/python3.8/site-packages/websockets/legacy/client.py", line 654, in __await_impl__
    _transport, protocol = await self._create_connection()
  File "uvloop/loop.pyx", line 2088, in create_connection
  File "uvloop/loop.pyx", line 2083, in uvloop.loop.Loop.create_connection
ConnectionResetError: [Errno 54] Connection reset by peer
2025-09-01 09:38:51,394 : WARNING : BINANCE_FUTURES.ws.1: encountered connection issue [Errno 54] Connection reset by peer - reconnecting in 16.0 seconds...
Traceback (most recent call last):
  File "/Users/aming/anaconda3/envs/quant/lib/python3.8/site-packages/cryptofeed/connection_handler.py", line 59, in _create_connection
    async with self.conn.connect() as connection:
  File "/Users/aming/anaconda3/envs/quant/lib/python3.8/contextlib.py", line 171, in __aenter__
    return await self.gen.__anext__()
  File "/Users/aming/anaconda3/envs/quant/lib/python3.8/site-packages/cryptofeed/connection.py", line 104, in connect
    await self._open()
  File "/Users/aming/anaconda3/envs/quant/lib/python3.8/site-packages/cryptofeed/connection.py", line 318, in _open
    self.conn = await websockets.connect(self.address, **self.ws_kwargs)
  File "/Users/aming/anaconda3/envs/quant/lib/python3.8/site-packages/websockets/legacy/client.py", line 654, in __await_impl__
    _transport, protocol = await self._create_connection()
  File "uvloop/loop.pyx", line 2088, in create_connection
  File "uvloop/loop.pyx", line 2083, in uvloop.loop.Loop.create_connection
ConnectionResetError: [Errno 54] Connection reset by peer
2025-09-01 09:40:39,023 : WARNING : BINANCE_FUTURES.ws.1: encountered connection issue [Errno 54] Connection reset by peer - reconnecting in 1.0 seconds...
Traceback (most recent call last):
  File "/Users/aming/anaconda3/envs/quant/lib/python3.8/site-packages/cryptofeed/connection_handler.py", line 59, in _create_connection
    async with self.conn.connect() as connection:
  File "/Users/aming/anaconda3/envs/quant/lib/python3.8/contextlib.py", line 171, in __aenter__
    return await self.gen.__anext__()
  File "/Users/aming/anaconda3/envs/quant/lib/python3.8/site-packages/cryptofeed/connection.py", line 104, in connect
    await self._open()
  File "/Users/aming/anaconda3/envs/quant/lib/python3.8/site-packages/cryptofeed/connection.py", line 318, in _open
    self.conn = await websockets.connect(self.address, **self.ws_kwargs)
  File "/Users/aming/anaconda3/envs/quant/lib/python3.8/site-packages/websockets/legacy/client.py", line 654, in __await_impl__
    _transport, protocol = await self._create_connection()
  File "uvloop/loop.pyx", line 2088, in create_connection
  File "uvloop/loop.pyx", line 2083, in uvloop.loop.Loop.create_connection
ConnectionResetError: [Errno 54] Connection reset by peer
2025-09-01 09:40:40,157 : WARNING : BINANCE_FUTURES.ws.1: encountered connection issue [Errno 54] Connection reset by peer - reconnecting in 2.0 seconds...
Traceback (most recent call last):
  File "/Users/aming/anaconda3/envs/quant/lib/python3.8/site-packages/cryptofeed/connection_handler.py", line 59, in _create_connection
    async with self.conn.connect() as connection:
  File "/Users/aming/anaconda3/envs/quant/lib/python3.8/contextlib.py", line 171, in __aenter__
    return await self.gen.__anext__()
  File "/Users/aming/anaconda3/envs/quant/lib/python3.8/site-packages/cryptofeed/connection.py", line 104, in connect
    await self._open()
  File "/Users/aming/anaconda3/envs/quant/lib/python3.8/site-packages/cryptofeed/connection.py", line 318, in _open
    self.conn = await websockets.connect(self.address, **self.ws_kwargs)
  File "/Users/aming/anaconda3/envs/quant/lib/python3.8/site-packages/websockets/legacy/client.py", line 654, in __await_impl__
    _transport, protocol = await self._create_connection()
  File "uvloop/loop.pyx", line 2088, in create_connection
  File "uvloop/loop.pyx", line 2083, in uvloop.loop.Loop.create_connection
ConnectionResetError: [Errno 54] Connection reset by peer
2025-09-01 09:40:42,284 : WARNING : BINANCE_FUTURES.ws.1: encountered connection issue [Errno 54] Connection reset by peer - reconnecting in 4.0 seconds...
Traceback (most recent call last):
  File "/Users/aming/anaconda3/envs/quant/lib/python3.8/site-packages/cryptofeed/connection_handler.py", line 59, in _create_connection
    async with self.conn.connect() as connection:
  File "/Users/aming/anaconda3/envs/quant/lib/python3.8/contextlib.py", line 171, in __aenter__
    return await self.gen.__anext__()
  File "/Users/aming/anaconda3/envs/quant/lib/python3.8/site-packages/cryptofeed/connection.py", line 104, in connect
    await self._open()
  File "/Users/aming/anaconda3/envs/quant/lib/python3.8/site-packages/cryptofeed/connection.py", line 318, in _open
    self.conn = await websockets.connect(self.address, **self.ws_kwargs)
  File "/Users/aming/anaconda3/envs/quant/lib/python3.8/site-packages/websockets/legacy/client.py", line 654, in __await_impl__
    _transport, protocol = await self._create_connection()
  File "uvloop/loop.pyx", line 2088, in create_connection
  File "uvloop/loop.pyx", line 2083, in uvloop.loop.Loop.create_connection
ConnectionResetError: [Errno 54] Connection reset by peer
2025-09-01 09:40:46,386 : WARNING : BINANCE_FUTURES.ws.1: encountered connection issue [Errno 54] Connection reset by peer - reconnecting in 8.0 seconds...
Traceback (most recent call last):
  File "/Users/aming/anaconda3/envs/quant/lib/python3.8/site-packages/cryptofeed/connection_handler.py", line 59, in _create_connection
    async with self.conn.connect() as connection:
  File "/Users/aming/anaconda3/envs/quant/lib/python3.8/contextlib.py", line 171, in __aenter__
    return await self.gen.__anext__()
  File "/Users/aming/anaconda3/envs/quant/lib/python3.8/site-packages/cryptofeed/connection.py", line 104, in connect
    await self._open()
  File "/Users/aming/anaconda3/envs/quant/lib/python3.8/site-packages/cryptofeed/connection.py", line 318, in _open
    self.conn = await websockets.connect(self.address, **self.ws_kwargs)
  File "/Users/aming/anaconda3/envs/quant/lib/python3.8/site-packages/websockets/legacy/client.py", line 654, in __await_impl__
    _transport, protocol = await self._create_connection()
  File "uvloop/loop.pyx", line 2088, in create_connection
  File "uvloop/loop.pyx", line 2083, in uvloop.loop.Loop.create_connection
ConnectionResetError: [Errno 54] Connection reset by peer
2025-09-01 09:40:54,508 : WARNING : BINANCE_FUTURES.ws.1: encountered connection issue [Errno 54] Connection reset by peer - reconnecting in 16.0 seconds...
Traceback (most recent call last):
  File "/Users/aming/anaconda3/envs/quant/lib/python3.8/site-packages/cryptofeed/connection_handler.py", line 59, in _create_connection
    async with self.conn.connect() as connection:
  File "/Users/aming/anaconda3/envs/quant/lib/python3.8/contextlib.py", line 171, in __aenter__
    return await self.gen.__anext__()
  File "/Users/aming/anaconda3/envs/quant/lib/python3.8/site-packages/cryptofeed/connection.py", line 104, in connect
    await self._open()
  File "/Users/aming/anaconda3/envs/quant/lib/python3.8/site-packages/cryptofeed/connection.py", line 318, in _open
    self.conn = await websockets.connect(self.address, **self.ws_kwargs)
  File "/Users/aming/anaconda3/envs/quant/lib/python3.8/site-packages/websockets/legacy/client.py", line 654, in __await_impl__
    _transport, protocol = await self._create_connection()
  File "uvloop/loop.pyx", line 2088, in create_connection
  File "uvloop/loop.pyx", line 2083, in uvloop.loop.Loop.create_connection
ConnectionResetError: [Errno 54] Connection reset by peer
2025-09-01 09:41:10,641 : WARNING : BINANCE_FUTURES.ws.1: encountered connection issue [Errno 54] Connection reset by peer - reconnecting in 32.0 seconds...
Traceback (most recent call last):
  File "/Users/aming/anaconda3/envs/quant/lib/python3.8/site-packages/cryptofeed/connection_handler.py", line 59, in _create_connection
    async with self.conn.connect() as connection:
  File "/Users/aming/anaconda3/envs/quant/lib/python3.8/contextlib.py", line 171, in __aenter__
    return await self.gen.__anext__()
  File "/Users/aming/anaconda3/envs/quant/lib/python3.8/site-packages/cryptofeed/connection.py", line 104, in connect
    await self._open()
  File "/Users/aming/anaconda3/envs/quant/lib/python3.8/site-packages/cryptofeed/connection.py", line 318, in _open
    self.conn = await websockets.connect(self.address, **self.ws_kwargs)
  File "/Users/aming/anaconda3/envs/quant/lib/python3.8/site-packages/websockets/legacy/client.py", line 654, in __await_impl__
    _transport, protocol = await self._create_connection()
  File "uvloop/loop.pyx", line 2088, in create_connection
  File "uvloop/loop.pyx", line 2083, in uvloop.loop.Loop.create_connection
ConnectionResetError: [Errno 54] Connection reset by peer
2025-09-01 09:45:36,068 : WARNING : BINANCE_FUTURES.ws.1: encountered connection issue [Errno 54] Connection reset by peer - reconnecting in 1.0 seconds...
Traceback (most recent call last):
  File "/Users/aming/anaconda3/envs/quant/lib/python3.8/site-packages/cryptofeed/connection_handler.py", line 59, in _create_connection
    async with self.conn.connect() as connection:
  File "/Users/aming/anaconda3/envs/quant/lib/python3.8/contextlib.py", line 171, in __aenter__
    return await self.gen.__anext__()
  File "/Users/aming/anaconda3/envs/quant/lib/python3.8/site-packages/cryptofeed/connection.py", line 104, in connect
    await self._open()
  File "/Users/aming/anaconda3/envs/quant/lib/python3.8/site-packages/cryptofeed/connection.py", line 318, in _open
    self.conn = await websockets.connect(self.address, **self.ws_kwargs)
  File "/Users/aming/anaconda3/envs/quant/lib/python3.8/site-packages/websockets/legacy/client.py", line 654, in __await_impl__
    _transport, protocol = await self._create_connection()
  File "uvloop/loop.pyx", line 2088, in create_connection
  File "uvloop/loop.pyx", line 2083, in uvloop.loop.Loop.create_connection
ConnectionResetError: [Errno 54] Connection reset by peer
2025-09-01 09:45:37,195 : WARNING : BINANCE_FUTURES.ws.1: encountered connection issue [Errno 54] Connection reset by peer - reconnecting in 2.0 seconds...
Traceback (most recent call last):
  File "/Users/aming/anaconda3/envs/quant/lib/python3.8/site-packages/cryptofeed/connection_handler.py", line 59, in _create_connection
    async with self.conn.connect() as connection:
  File "/Users/aming/anaconda3/envs/quant/lib/python3.8/contextlib.py", line 171, in __aenter__
    return await self.gen.__anext__()
  File "/Users/aming/anaconda3/envs/quant/lib/python3.8/site-packages/cryptofeed/connection.py", line 104, in connect
    await self._open()
  File "/Users/aming/anaconda3/envs/quant/lib/python3.8/site-packages/cryptofeed/connection.py", line 318, in _open
    self.conn = await websockets.connect(self.address, **self.ws_kwargs)
  File "/Users/aming/anaconda3/envs/quant/lib/python3.8/site-packages/websockets/legacy/client.py", line 654, in __await_impl__
    _transport, protocol = await self._create_connection()
  File "uvloop/loop.pyx", line 2088, in create_connection
  File "uvloop/loop.pyx", line 2083, in uvloop.loop.Loop.create_connection
ConnectionResetError: [Errno 54] Connection reset by peer
2025-09-01 09:45:39,293 : WARNING : BINANCE_FUTURES.ws.1: encountered connection issue [Errno 54] Connection reset by peer - reconnecting in 4.0 seconds...
Traceback (most recent call last):
  File "/Users/aming/anaconda3/envs/quant/lib/python3.8/site-packages/cryptofeed/connection_handler.py", line 59, in _create_connection
    async with self.conn.connect() as connection:
  File "/Users/aming/anaconda3/envs/quant/lib/python3.8/contextlib.py", line 171, in __aenter__
    return await self.gen.__anext__()
  File "/Users/aming/anaconda3/envs/quant/lib/python3.8/site-packages/cryptofeed/connection.py", line 104, in connect
    await self._open()
  File "/Users/aming/anaconda3/envs/quant/lib/python3.8/site-packages/cryptofeed/connection.py", line 318, in _open
    self.conn = await websockets.connect(self.address, **self.ws_kwargs)
  File "/Users/aming/anaconda3/envs/quant/lib/python3.8/site-packages/websockets/legacy/client.py", line 654, in __await_impl__
    _transport, protocol = await self._create_connection()
  File "uvloop/loop.pyx", line 2088, in create_connection
  File "uvloop/loop.pyx", line 2083, in uvloop.loop.Loop.create_connection
ConnectionResetError: [Errno 54] Connection reset by peer
2025-09-01 09:51:43,645 : WARNING : BINANCE_FUTURES.ws.1: encountered connection issue [Errno 54] Connection reset by peer - reconnecting in 1.0 seconds...
Traceback (most recent call last):
  File "/Users/aming/anaconda3/envs/quant/lib/python3.8/site-packages/cryptofeed/connection_handler.py", line 59, in _create_connection
    async with self.conn.connect() as connection:
  File "/Users/aming/anaconda3/envs/quant/lib/python3.8/contextlib.py", line 171, in __aenter__
    return await self.gen.__anext__()
  File "/Users/aming/anaconda3/envs/quant/lib/python3.8/site-packages/cryptofeed/connection.py", line 104, in connect
    await self._open()
  File "/Users/aming/anaconda3/envs/quant/lib/python3.8/site-packages/cryptofeed/connection.py", line 318, in _open
    self.conn = await websockets.connect(self.address, **self.ws_kwargs)
  File "/Users/aming/anaconda3/envs/quant/lib/python3.8/site-packages/websockets/legacy/client.py", line 654, in __await_impl__
    _transport, protocol = await self._create_connection()
  File "uvloop/loop.pyx", line 2088, in create_connection
  File "uvloop/loop.pyx", line 2083, in uvloop.loop.Loop.create_connection
ConnectionResetError: [Errno 54] Connection reset by peer
2025-09-01 09:51:44,762 : WARNING : BINANCE_FUTURES.ws.1: encountered connection issue [Errno 54] Connection reset by peer - reconnecting in 2.0 seconds...
Traceback (most recent call last):
  File "/Users/aming/anaconda3/envs/quant/lib/python3.8/site-packages/cryptofeed/connection_handler.py", line 59, in _create_connection
    async with self.conn.connect() as connection:
  File "/Users/aming/anaconda3/envs/quant/lib/python3.8/contextlib.py", line 171, in __aenter__
    return await self.gen.__anext__()
  File "/Users/aming/anaconda3/envs/quant/lib/python3.8/site-packages/cryptofeed/connection.py", line 104, in connect
    await self._open()
  File "/Users/aming/anaconda3/envs/quant/lib/python3.8/site-packages/cryptofeed/connection.py", line 318, in _open
    self.conn = await websockets.connect(self.address, **self.ws_kwargs)
  File "/Users/aming/anaconda3/envs/quant/lib/python3.8/site-packages/websockets/legacy/client.py", line 654, in __await_impl__
    _transport, protocol = await self._create_connection()
  File "uvloop/loop.pyx", line 2088, in create_connection
  File "uvloop/loop.pyx", line 2083, in uvloop.loop.Loop.create_connection
ConnectionResetError: [Errno 54] Connection reset by peer
2025-09-01 09:51:46,884 : WARNING : BINANCE_FUTURES.ws.1: encountered connection issue [Errno 54] Connection reset by peer - reconnecting in 4.0 seconds...
Traceback (most recent call last):
  File "/Users/aming/anaconda3/envs/quant/lib/python3.8/site-packages/cryptofeed/connection_handler.py", line 59, in _create_connection
    async with self.conn.connect() as connection:
  File "/Users/aming/anaconda3/envs/quant/lib/python3.8/contextlib.py", line 171, in __aenter__
    return await self.gen.__anext__()
  File "/Users/aming/anaconda3/envs/quant/lib/python3.8/site-packages/cryptofeed/connection.py", line 104, in connect
    await self._open()
  File "/Users/aming/anaconda3/envs/quant/lib/python3.8/site-packages/cryptofeed/connection.py", line 318, in _open
    self.conn = await websockets.connect(self.address, **self.ws_kwargs)
  File "/Users/aming/anaconda3/envs/quant/lib/python3.8/site-packages/websockets/legacy/client.py", line 654, in __await_impl__
    _transport, protocol = await self._create_connection()
  File "uvloop/loop.pyx", line 2088, in create_connection
  File "uvloop/loop.pyx", line 2083, in uvloop.loop.Loop.create_connection
ConnectionResetError: [Errno 54] Connection reset by peer
2025-09-01 09:51:51,006 : WARNING : BINANCE_FUTURES.ws.1: encountered connection issue [Errno 54] Connection reset by peer - reconnecting in 8.0 seconds...
Traceback (most recent call last):
  File "/Users/aming/anaconda3/envs/quant/lib/python3.8/site-packages/cryptofeed/connection_handler.py", line 59, in _create_connection
    async with self.conn.connect() as connection:
  File "/Users/aming/anaconda3/envs/quant/lib/python3.8/contextlib.py", line 171, in __aenter__
    return await self.gen.__anext__()
  File "/Users/aming/anaconda3/envs/quant/lib/python3.8/site-packages/cryptofeed/connection.py", line 104, in connect
    await self._open()
  File "/Users/aming/anaconda3/envs/quant/lib/python3.8/site-packages/cryptofeed/connection.py", line 318, in _open
    self.conn = await websockets.connect(self.address, **self.ws_kwargs)
  File "/Users/aming/anaconda3/envs/quant/lib/python3.8/site-packages/websockets/legacy/client.py", line 654, in __await_impl__
    _transport, protocol = await self._create_connection()
  File "uvloop/loop.pyx", line 2088, in create_connection
  File "uvloop/loop.pyx", line 2083, in uvloop.loop.Loop.create_connection
ConnectionResetError: [Errno 54] Connection reset by peer
2025-09-01 09:51:59,142 : WARNING : BINANCE_FUTURES.ws.1: encountered connection issue [Errno 54] Connection reset by peer - reconnecting in 16.0 seconds...
Traceback (most recent call last):
  File "/Users/aming/anaconda3/envs/quant/lib/python3.8/site-packages/cryptofeed/connection_handler.py", line 59, in _create_connection
    async with self.conn.connect() as connection:
  File "/Users/aming/anaconda3/envs/quant/lib/python3.8/contextlib.py", line 171, in __aenter__
    return await self.gen.__anext__()
  File "/Users/aming/anaconda3/envs/quant/lib/python3.8/site-packages/cryptofeed/connection.py", line 104, in connect
    await self._open()
  File "/Users/aming/anaconda3/envs/quant/lib/python3.8/site-packages/cryptofeed/connection.py", line 318, in _open
    self.conn = await websockets.connect(self.address, **self.ws_kwargs)
  File "/Users/aming/anaconda3/envs/quant/lib/python3.8/site-packages/websockets/legacy/client.py", line 654, in __await_impl__
    _transport, protocol = await self._create_connection()
  File "uvloop/loop.pyx", line 2088, in create_connection
  File "uvloop/loop.pyx", line 2083, in uvloop.loop.Loop.create_connection
ConnectionResetError: [Errno 54] Connection reset by peer
2025-09-01 09:52:15,251 : WARNING : BINANCE_FUTURES.ws.1: encountered connection issue [Errno 54] Connection reset by peer - reconnecting in 32.0 seconds...
Traceback (most recent call last):
  File "/Users/aming/anaconda3/envs/quant/lib/python3.8/site-packages/cryptofeed/connection_handler.py", line 59, in _create_connection
    async with self.conn.connect() as connection:
  File "/Users/aming/anaconda3/envs/quant/lib/python3.8/contextlib.py", line 171, in __aenter__
    return await self.gen.__anext__()
  File "/Users/aming/anaconda3/envs/quant/lib/python3.8/site-packages/cryptofeed/connection.py", line 104, in connect
    await self._open()
  File "/Users/aming/anaconda3/envs/quant/lib/python3.8/site-packages/cryptofeed/connection.py", line 318, in _open
    self.conn = await websockets.connect(self.address, **self.ws_kwargs)
  File "/Users/aming/anaconda3/envs/quant/lib/python3.8/site-packages/websockets/legacy/client.py", line 654, in __await_impl__
    _transport, protocol = await self._create_connection()
  File "uvloop/loop.pyx", line 2088, in create_connection
  File "uvloop/loop.pyx", line 2083, in uvloop.loop.Loop.create_connection
ConnectionResetError: [Errno 54] Connection reset by peer
2025-09-01 09:52:47,401 : WARNING : BINANCE_FUTURES.ws.1: encountered connection issue [Errno 54] Connection reset by peer - reconnecting in 64.0 seconds...
Traceback (most recent call last):
  File "/Users/aming/anaconda3/envs/quant/lib/python3.8/site-packages/cryptofeed/connection_handler.py", line 59, in _create_connection
    async with self.conn.connect() as connection:
  File "/Users/aming/anaconda3/envs/quant/lib/python3.8/contextlib.py", line 171, in __aenter__
    return await self.gen.__anext__()
  File "/Users/aming/anaconda3/envs/quant/lib/python3.8/site-packages/cryptofeed/connection.py", line 104, in connect
    await self._open()
  File "/Users/aming/anaconda3/envs/quant/lib/python3.8/site-packages/cryptofeed/connection.py", line 318, in _open
    self.conn = await websockets.connect(self.address, **self.ws_kwargs)
  File "/Users/aming/anaconda3/envs/quant/lib/python3.8/site-packages/websockets/legacy/client.py", line 654, in __await_impl__
    _transport, protocol = await self._create_connection()
  File "uvloop/loop.pyx", line 2088, in create_connection
  File "uvloop/loop.pyx", line 2083, in uvloop.loop.Loop.create_connection
ConnectionResetError: [Errno 54] Connection reset by peer
